<?xml version="1.0"?>
<robot xmlns:xacro="http://www.ros.org/wiki/xacro" name="multi_story_car">

  <xacro:arg name="robot_name" default="robot_1"/>

  <link name="base_footprint"/>

  <joint name="base_joint" type="fixed">
    <parent link="base_footprint"/>
    <child link="base_link"/>
    <origin xyz="0.0 0.0 0.11" rpy="0.0 0.0 0.0"/>
  </joint>

  <link name="base_link">
    <visual>
      <geometry>
        <cylinder radius="0.2" length="0.1"/>
      </geometry>
      <material name="chassis_mat">
        <color rgba="0.0 0.0 0.8 1.0"/>
      </material>
    </visual>
    <collision>
      <geometry>
        <cylinder radius="0.2" length="0.1"/>
      </geometry>
    </collision>
    <inertial>
      <mass value="5.0"/>
      <origin xyz="0 0 0" rpy="0 0 0"/>
      <inertia ixx="0.054" ixy="0.0" ixz="0.0" iyy="0.054" iyz="0.0" izz="0.1"/>
    </inertial>
  </link>

  <joint name="deck_joint" type="fixed">
    <parent link="base_link"/>
    <child link="upper_deck_link"/>
    <origin xyz="0.0 0.0 0.15" rpy="0.0 0.0 0.0"/>
  </joint>

  <link name="upper_deck_link">
    <visual>
      <geometry>
        <cylinder radius="0.2" length="0.02"/>
      </geometry>
      <material name="deck_mat">
        <color rgba="0.7 0.7 0.7 1.0"/>
      </material>
    </visual>
    <collision>
      <geometry>
        <cylinder radius="0.2" length="0.02"/>
      </geometry>
    </collision>
    <inertial>
      <mass value="1.0"/>
      <origin xyz="0 0 0" rpy="0 0 0"/>
      <inertia ixx="0.01" ixy="0.0" ixz="0.0" iyy="0.01" iyz="0.0" izz="0.02"/>
    </inertial>
  </link>

  <joint name="left_wheel_joint" type="continuous">
    <parent link="base_link"/>
    <child link="left_wheel_link"/>
    <origin xyz="0.0 0.23 -0.05" rpy="-1.5708 0.0 0.0"/>
    <axis xyz="0.0 0.0 1.0"/>
  </joint>

  <link name="left_wheel_link">
    <visual>
      <geometry>
        <cylinder radius="0.06" length="0.04"/>
      </geometry>
      <material name="wheel_l_mat">
        <color rgba="0.0 0.0 0.0 1.0"/>
      </material>
    </visual>
    <collision>
      <geometry>
        <cylinder radius="0.06" length="0.04"/>
      </geometry>
    </collision>
    <inertial>
      <mass value="0.4"/>
      <inertia ixx="0.00019" ixy="0.0" ixz="0.0" iyy="0.00019" iyz="0.0" izz="0.00032"/>
    </inertial>
  </link>

  <joint name="right_wheel_joint" type="continuous">
    <parent link="base_link"/>
    <child link="right_wheel_link"/>
    <origin xyz="0.0 -0.23 -0.05" rpy="-1.5708 0.0 0.0"/>
    <axis xyz="0.0 0.0 1.0"/>
  </joint>

  <link name="right_wheel_link">
    <visual>
      <geometry>
        <cylinder radius="0.06" length="0.04"/>
      </geometry>
      <material name="wheel_r_mat">
        <color rgba="0.0 0.0 0.0 1.0"/>
      </material>
    </visual>
    <collision>
      <geometry>
        <cylinder radius="0.06" length="0.04"/>
      </geometry>
    </collision>
    <inertial>
      <mass value="0.4"/>
      <inertia ixx="0.00019" ixy="0.0" ixz="0.0" iyy="0.00019" iyz="0.0" izz="0.00032"/>
    </inertial>
  </link>

  <joint name="front_caster_joint" type="fixed">
    <parent link="base_link"/>
    <child link="front_caster_link"/>
    <origin xyz="0.15 0.0 -0.089" rpy="0.0 0.0 0.0"/>
  </joint>

  <link name="front_caster_link">
    <visual>
      <geometry>
        <sphere radius="0.02"/>
      </geometry>
      <material name="caster_f_mat">
        <color rgba="0.2 0.2 0.2 1.0"/>
      </material>
    </visual>
    <collision>
      <geometry>
        <sphere radius="0.02"/>
      </geometry>
    </collision>
    <inertial>
      <mass value="0.1"/>
      <inertia ixx="0.000016" ixy="0.0" ixz="0.0" iyy="0.000016" iyz="0.0" izz="0.000016"/>
    </inertial>
  </link>

  <joint name="rear_caster_joint" type="fixed">
    <parent link="base_link"/>
    <child link="rear_caster_link"/>
    <origin xyz="-0.15 0.0 -0.089" rpy="0.0 0.0 0.0"/>
  </joint>

  <link name="rear_caster_link">
    <visual>
      <geometry>
        <sphere radius="0.02"/>
      </geometry>
      <material name="caster_b_mat">
        <color rgba="0.2 0.2 0.2 1.0"/>
      </material>
    </visual>
    <collision>
      <geometry>
        <sphere radius="0.02"/>
      </geometry>
    </collision>
    <inertial>
      <mass value="0.1"/>
      <inertia ixx="0.000016" ixy="0.0" ixz="0.0" iyy="0.000016" iyz="0.0" izz="0.000016"/>
    </inertial>
  </link>

  <joint name="laser_joint" type="fixed">
    <parent link="upper_deck_link"/>
    <child link="laser_link"/>
    <origin xyz="0.0 0.0 0.04" rpy="0.0 0.0 0.0"/>
  </joint>

  <link name="laser_link">
    <visual>
      <geometry>
        <cylinder radius="0.03" length="0.04"/>
      </geometry>
      <material name="laser_mat">
        <color rgba="0.0 0.0 0.0 1.0"/>
      </material>
    </visual>
    <collision>
      <geometry>
        <cylinder radius="0.03" length="0.04"/>
      </geometry>
    </collision>
    <inertial>
      <mass value="0.1"/>
      <inertia ixx="0.00002" ixy="0.0" ixz="0.0" iyy="0.00002" iyz="0.0" izz="0.00004"/>
    </inertial>
  </link>

  <joint name="camera_joint" type="fixed">
    <parent link="upper_deck_link"/>
    <child link="camera_link"/>
    <origin xyz="0.19 0.0 0.02" rpy="0.0 0.0 0.0"/>
  </joint>

  <link name="camera_link">
    <visual>
      <geometry>
        <box size="0.02 0.04 0.03"/>
      </geometry>
      <material name="camera_mat">
        <color rgba="0.0 0.0 0.0 1.0"/>
      </material>
    </visual>
    <collision>
      <geometry>
        <box size="0.02 0.04 0.03"/>
      </geometry>
    </collision>
    <inertial>
      <mass value="0.05"/>
      <inertia ixx="0.00001" ixy="0.0" ixz="0.0" iyy="0.00001" iyz="0.0" izz="0.00001"/>
    </inertial>
  </link>

  <gazebo reference="base_link">
    <material>Gazebo/Blue</material>
    <laserRetro>50.0</laserRetro>
  </gazebo>

  <gazebo reference="upper_deck_link">
    <material>Gazebo/Grey</material>
    <laserRetro>50.0</laserRetro>
  </gazebo>

  <gazebo reference="left_wheel_link">
    <mu1 value="2.5"/>
    <mu2 value="2.5"/>
    <material>Gazebo/Black</material>
    <laserRetro>30.0</laserRetro>
  </gazebo>

  <gazebo reference="right_wheel_link">
    <mu1 value="2.5"/>
    <mu2 value="2.5"/>
    <material>Gazebo/Black</material>
    <laserRetro>30.0</laserRetro>
  </gazebo>

  <gazebo reference="front_caster_link">
    <mu1 value="0.0001"/>
    <mu2 value="0.0001"/>
    <material>Gazebo/DarkGrey</material>
  </gazebo>

  <gazebo reference="rear_caster_link">
    <mu1 value="0.0001"/>
    <mu2 value="0.0001"/>
    <material>Gazebo/DarkGrey</material>
  </gazebo>

  <gazebo>
    <plugin name="diff_drive" filename="libgazebo_ros_diff_drive.so">
      <ros>
        <namespace>/$(arg robot_name)</namespace>
        <remapping>cmd_vel:=cmd_vel</remapping>
        <remapping>odom:=odom</remapping>
      </ros>
      <left_joint>left_wheel_joint</left_joint>
      <right_joint>right_wheel_joint</right_joint>
      <wheel_separation>0.46</wheel_separation>
      <wheel_diameter>0.12</wheel_diameter>
      <max_wheel_torque>35</max_wheel_torque>
      <max_wheel_acceleration>2.5</max_wheel_acceleration>
      <publish_odom>true</publish_odom>
      <publish_odom_tf>true</publish_odom_tf>
      <publish_wheel_tf>true</publish_wheel_tf>
      <odometry_frame>odom</odometry_frame>
      <robot_base_frame>base_footprint</robot_base_frame>
    </plugin>
  </gazebo>

  <gazebo reference="laser_link">
    <sensor type="ray" name="laser_sensor">
      <pose>0 0 0 0 0 0</pose>
      <visualize>false</visualize>
      <update_rate>10</update_rate>
      <ray>
        <scan>
          <horizontal>
            <samples>360</samples>
            <resolution>1</resolution>
            <min_angle>-3.14159</min_angle>
            <max_angle>3.14159</max_angle>
          </horizontal>
        </scan>
        <range>
          <min>0.21</min>
          <max>12.0</max>
          <resolution>0.01</resolution>
        </range>
      </ray>
      <plugin name="laser_controller" filename="libgazebo_ros_ray_sensor.so">
        <ros>
          <namespace>/$(arg robot_name)</namespace>
          <remapping>~/out:=scan</remapping>
        </ros>
        <output_type>sensor_msgs/LaserScan</output_type>
        <frame_name>laser_link</frame_name>
      </plugin>
    </sensor>
  </gazebo>

  <gazebo reference="camera_link">
    <sensor type="camera" name="camera_sensor">
      <update_rate>30.0</update_rate>
      <camera name="head">
        <horizontal_fov>1.3962634</horizontal_fov>
        <image>
          <width>320</width>
          <height>240</height>
          <format>R8G8B8</format>
        </image>
        <clip>
          <near>0.02</near>
          <far>100.0</far>
        </clip>
      </camera>
      <plugin name="camera_controller" filename="libgazebo_ros_camera.so">
        <ros>
          <namespace>/$(arg robot_name)</namespace>
          <remapping>image_raw:=camera/image_raw</remapping>
        </ros>
        <frame_name>camera_link</frame_name>
      </plugin>
    </sensor>
  </gazebo>

</robot>